<?xml version="1.0" ?>
<sdf version='1.6'>
  <model name='MovoSevenDOF'>
    <link name='base_link'>
      <pose frame=''>0 0 0 0 -0 0</pose>
      <inertial>
        <pose frame=''>-0.002974 -0.008419 0.237851 0 -0 0</pose>
        <mass>67.9184</mass>
        <inertia>
          <ixx>3.97207</ixx>
          <ixy>-0.00341811</ixy>
          <ixz>-0.0764064</ixz>
          <iyy>4.23328</iyy>
          <iyz>-0.075981</iyz>
          <izz>0.697625</izz>
        </inertia>
      </inertial>
      <collision name='base_link_fixed_joint_lump__base_chassis_link_collision'>
        <pose frame=''>0 0 0.0762 0 -0 0</pose>
        <geometry>
          <mesh>
            <scale>1 1 1</scale>
            <uri>file://MovoRobot/movo_description//meshes/movo_components/collision/vector_base_collision.stl</uri>
          </mesh>
        </geometry>
        <surface>
          <contact>
            <ode/>
          </contact>
          <friction>
            <ode>
              <mu>0</mu>
            </ode>
          </friction>
        </surface>
        <laser_retro>0</laser_retro>
      </collision>
      <collision name='base_link_fixed_joint_lump__front_laser_link_collision_1'>
        <pose frame=''>0.3375 0 0.220111 3.14159 -0 0</pose>
        <geometry>
          <box>
            <size>0.1 0.1 0.1</size>
          </box>
        </geometry>
        <surface>
          <contact>
            <ode/>
          </contact>
          <friction>
            <ode/>
          </friction>
        </surface>
      </collision>
      <collision name='base_link_fixed_joint_lump__linear_actuator_fixed_link_collision_2'>
        <pose frame=''>0 0 0.0762 0 -0 0</pose>
        <geometry>
          <mesh>
            <scale>1 1 1</scale>
            <uri>file://MovoRobot/movo_description//meshes/movo_components/collision/movo_fixed_body_collision.stl</uri>
          </mesh>
        </geometry>
        <surface>
          <contact>
            <ode/>
          </contact>
          <friction>
            <ode/>
          </friction>
        </surface>
        <laser_retro>0</laser_retro>
      </collision>
      <collision name='base_link_fixed_joint_lump__rear_laser_link_collision_3'>
        <pose frame=''>-0.3375 0 0.220111 3.14159 -0 3.14159</pose>
        <geometry>
          <box>
            <size>0.1 0.1 0.1</size>
          </box>
        </geometry>
        <surface>
          <contact>
            <ode/>
          </contact>
          <friction>
            <ode/>
          </friction>
        </surface>
      </collision>
      <visual name='base_link_fixed_joint_lump__base_chassis_link_visual'>
        <pose frame=''>0 0 0.0762 0 -0 0</pose>
        <geometry>
          <mesh>
            <scale>1 1 1</scale>
            <uri>file://MovoRobot/movo_description//meshes/movo_components/visual/vector_base.dae</uri>
          </mesh>
        </geometry>
        <material>
          <script>
            <uri>__default__</uri>
            <name>__default__</name>
          </script>
        </material>
      </visual>
      <visual name='base_link_fixed_joint_lump__front_laser_link_visual_1'>
        <pose frame=''>0.3375 0 0.220111 3.14159 -0 0</pose>
        <geometry>
          <mesh>
            <scale>1 1 1</scale>
            <uri>file://MovoRobot/movo_description//meshes/sensors/visual/sick_tim.dae</uri>
          </mesh>
        </geometry>
        <material>
          <script>
            <uri>__default__</uri>
            <name>__default__</name>
          </script>
        </material>
      </visual>
      <visual name='base_link_fixed_joint_lump__linear_actuator_fixed_link_visual_2'>
        <pose frame=''>0 0 0.0762 0 -0 0</pose>
        <geometry>
          <mesh>
            <scale>1 1 1</scale>
            <uri>file://MovoRobot/movo_description//meshes/movo_components/visual/movo_fixed_payload.dae</uri>
          </mesh>
        </geometry>
        <material>
          <script>
            <uri>__default__</uri>
            <name>__default__</name>
          </script>
        </material>
      </visual>
      <visual name='base_link_fixed_joint_lump__lower_body_link_visual_3'>
        <pose frame=''>0 0 0.0762 0 -0 0</pose>
        <geometry>
          <mesh>
            <scale>1 1 1</scale>
            <uri>file://MovoRobot/movo_description//meshes/movo_body/movo_lower_body.dae</uri>
          </mesh>
        </geometry>
      </visual>
      <visual name='base_link_fixed_joint_lump__rear_laser_link_visual_4'>
        <pose frame=''>-0.3375 0 0.220111 3.14159 -0 3.14159</pose>
        <geometry>
          <mesh>
            <scale>1 1 1</scale>
            <uri>file://MovoRobot/movo_description//meshes/sensors/visual/sick_tim.dae</uri>
          </mesh>
        </geometry>
        <material>
          <script>
            <uri>__default__</uri>
            <name>__default__</name>
          </script>
        </material>
      </visual>
      <velocity_decay/>
      <velocity_decay/>
      <velocity_decay/>
      <velocity_decay/>
      <!--sensor name='front_laser' type='ray'>
        <visualize>0</visualize>
        <update_rate>15</update_rate>
        <ray>
          <scan>
            <horizontal>
              <samples>720</samples>
              <resolution>1</resolution>
              <min_angle>-2</min_angle>
              <max_angle>2</max_angle>
            </horizontal>
          </scan>
          <range>
            <min>0.1</min>
            <max>25</max>
            <resolution>0.01</resolution>
          </range>
          <noise>
            <type>gaussian</type>
            <mean>0</mean>
            <stddev>0.01</stddev>
          </noise>
        </ray>
        <plugin name='front_laser_node' filename='libgazebo_ros_laser.so'>
          <topicName>/movo/front_scan</topicName>
          <frameName>front_laser_link</frameName>
        </plugin>
        <pose frame=''>0.3375 0 0.220111 3.14159 -0 0</pose>
      </sensor-->
      <velocity_decay/>
      <gravity>1</gravity>
      <velocity_decay/>
      <self_collide>0</self_collide>
      <!--sensor name='rear_laser' type='ray'>
        <visualize>0</visualize>
        <update_rate>15</update_rate>
        <ray>
          <scan>
            <horizontal>
              <samples>720</samples>
              <resolution>1</resolution>
              <min_angle>-2</min_angle>
              <max_angle>2</max_angle>
            </horizontal>
          </scan>
          <range>
            <min>0.1</min>
            <max>25</max>
            <resolution>0.01</resolution>
          </range>
          <noise>
            <type>gaussian</type>
            <mean>0</mean>
            <stddev>0.01</stddev>
          </noise>
        </ray>
        <plugin name='rear_laser_node' filename='libgazebo_ros_laser.so'>
          <topicName>/movo/rear_scan</topicName>
          <frameName>rear_laser_link</frameName>
        </plugin>
        <pose frame=''>-0.3375 0 0.220111 3.14159 -0 3.14159</pose>
      </sensor-->
    </link>
    <link name='linear_actuator_link'>
      <pose frame=''>0.07714 0 0.470076 0 -0 0</pose>
      <inertial>
        <pose frame=''>-0.06514 -0.002828 0.356497 0 -0 0</pose>
        <mass>20.7437</mass>
        <inertia>
          <ixx>0.8115</ixx>
          <ixy>-0.0106441</ixy>
          <ixz>-0.0608701</ixz>
          <iyy>0.839619</iyy>
          <iyz>-0.022887</iyz>
          <izz>0.666234</izz>
        </inertia>
      </inertial>
      <collision name='linear_actuator_link_collision'>
        <pose frame=''>0 0 0 0 -0 0</pose>
        <geometry>
          <mesh>
            <scale>1 1 1</scale>
            <uri>file://MovoRobot/movo_description//meshes/movo_components/collision/movo_upper_body_collision.stl</uri>
          </mesh>
        </geometry>
        <surface>
          <contact>
            <ode/>
          </contact>
          <friction>
            <ode/>
          </friction>
        </surface>
        <laser_retro>0</laser_retro>
      </collision>
      <collision name='linear_actuator_link_fixed_joint_lump__left_base_link_collision_1'>
        <pose frame=''>0.026105 0.13335 0.279994 -1.5708 -0 -1.5708</pose>
        <geometry>
          <mesh>
            <scale>1 1 1</scale>
            <uri>file://MovoRobot/movo_description//meshes/manipulation/jaco/collision/base.stl</uri>
          </mesh>
        </geometry>
        <surface>
          <contact>
            <ode>
              <kp>1e+06</kp>
              <kd>100</kd>
              <max_vel>100</max_vel>
              <min_depth>0.001</min_depth>
            </ode>
          </contact>
          <friction>
            <ode>
              <mu>1</mu>
              <mu2>1</mu2>
            </ode>
          </friction>
        </surface>
      </collision>
      <collision name='linear_actuator_link_fixed_joint_lump__pan_base_link_collision_2'>
        <pose frame=''>0.19735 0 0.344989 0 -0 0</pose>
        <geometry>
          <mesh>
            <scale>1 1 1</scale>
            <uri>file://MovoRobot/movo_description//meshes/pan_tilt/collision/pan_tilt_base.stl</uri>
          </mesh>
        </geometry>
      </collision>
      <collision name='linear_actuator_link_fixed_joint_lump__right_base_link_collision_3'>
        <pose frame=''>0.026105 -0.13335 0.279994 -1.5708 -0 -1.5708</pose>
        <geometry>
          <mesh>
            <scale>1 1 1</scale>
            <uri>file://MovoRobot/movo_description//meshes/manipulation/jaco/collision/base.stl</uri>
          </mesh>
        </geometry>
        <surface>
          <contact>
            <ode>
              <kp>1e+06</kp>
              <kd>100</kd>
              <max_vel>100</max_vel>
              <min_depth>0.001</min_depth>
            </ode>
          </contact>
          <friction>
            <ode>
              <mu>1</mu>
              <mu2>1</mu2>
            </ode>
          </friction>
        </surface>
      </collision>
      <visual name='linear_actuator_link_visual'>
        <pose frame=''>0 0 0 0 -0 0</pose>
        <geometry>
          <mesh>
            <scale>1 1 1</scale>
            <uri>file://MovoRobot/movo_description//meshes/movo_components/visual/movo_moving_payload.dae</uri>
          </mesh>
        </geometry>
        <material>
          <script>
            <uri>__default__</uri>
            <name>__default__</name>
          </script>
        </material>
      </visual>
      <visual name='linear_actuator_link_fixed_joint_lump__left_base_link_visual_1'>
        <pose frame=''>0.026105 0.13335 0.279994 -1.5708 -0 -1.5708</pose>
        <geometry>
          <mesh>
            <scale>1 1 1</scale>
            <uri>file://MovoRobot/movo_description//meshes/manipulation/jaco/visual/base.dae</uri>
          </mesh>
        </geometry>
        <material>
          <script>
            <uri>__default__</uri>
            <name>__default__</name>
          </script>
        </material>
      </visual>
      <visual name='linear_actuator_link_fixed_joint_lump__pan_base_link_visual_2'>
        <pose frame=''>0.19735 0 0.344989 0 -0 0</pose>
        <geometry>
          <mesh>
            <scale>1 1 1</scale>
            <uri>file://MovoRobot/movo_description//meshes/pan_tilt/visual/pan_tilt_base.dae</uri>
          </mesh>
        </geometry>
      </visual>
      <visual name='linear_actuator_link_fixed_joint_lump__right_base_link_visual_3'>
        <pose frame=''>0.026105 -0.13335 0.279994 -1.5708 -0 -1.5708</pose>
        <geometry>
          <mesh>
            <scale>1 1 1</scale>
            <uri>file://MovoRobot/movo_description//meshes/manipulation/jaco/visual/base.dae</uri>
          </mesh>
        </geometry>
        <material>
          <script>
            <uri>__default__</uri>
            <name>__default__</name>
          </script>
        </material>
      </visual>
      <visual name='linear_actuator_link_fixed_joint_lump__upper_body_link_visual_4'>
        <pose frame=''>0 0 0 0 -0 0</pose>
        <geometry>
          <mesh>
            <scale>1 1 1</scale>
            <uri>file://MovoRobot/movo_description//meshes/movo_body/movo_upper_body.dae</uri>
          </mesh>
        </geometry>
      </visual>
      <velocity_decay/>
      <velocity_decay/>
      <gravity>1</gravity>
      <velocity_decay/>
      <self_collide>0</self_collide>
    </link>
    <joint name='linear_joint' type='prismatic'>
      <child>linear_actuator_link</child>
      <parent>base_link</parent>
      <axis>
        <xyz>0 0 1</xyz>
        <limit>
          <lower>0</lower>
          <upper>0.472</upper>
          <effort>1000</effort>
          <velocity>0.2</velocity>
        </limit>
        <dynamics>
          <damping>0</damping>
          <friction>0</friction>
          <spring_reference>0</spring_reference>
          <spring_stiffness>0</spring_stiffness>
        </dynamics>
        <use_parent_model_frame>1</use_parent_model_frame>
      </axis>
    </joint>
    <!-- <link name='left_shoulder_link'>
      <pose frame=''>0.165745 0.13335 0.75007 -1.5708 0 1.5708</pose>
      <inertial>
        <pose frame=''>1.8e-05 -0.004667 -0.060609 0 -0 0</pose>
        <mass>0.824524</mass>
        <inertia>
          <ixx>0.002561</ixx>
          <ixy>0</ixy>
          <ixz>1e-06</ixz>
          <iyy>0.002653</iyy>
          <iyz>0.000212</iyz>
          <izz>0.000524</izz>
        </inertia>
      </inertial>
      <collision name='left_shoulder_link_collision'>
        <pose frame=''>0 0 0 0 -0 0</pose>
        <geometry>
          <mesh>
            <scale>1 1 1</scale>
            <uri>file://MovoRobot/movo_description//meshes/manipulation/jaco/collision/shoulder_7dof.stl</uri>
          </mesh>
        </geometry>
        <surface>
          <contact>
            <ode>
              <kp>1e+06</kp>
              <kd>100</kd>
              <max_vel>100</max_vel>
              <min_depth>0.001</min_depth>
            </ode>
          </contact>
          <friction>
            <ode>
              <mu>1</mu>
              <mu2>1</mu2>
            </ode>
          </friction>
        </surface>
      </collision>
      <visual name='left_shoulder_link_visual'>
        <pose frame=''>0 0 0 0 -0 0</pose>
        <geometry>
          <mesh>
            <scale>1 1 1</scale>
            <uri>file://MovoRobot/movo_description//meshes/manipulation/jaco/visual/shoulder_7dof.dae</uri>
          </mesh>
        </geometry>
        <material>
          <script>
            <uri>__default__</uri>
            <name>__default__</name>
          </script>
        </material>
      </visual>
      <gravity>1</gravity>
      <velocity_decay/>
      <self_collide>0</self_collide>
    </link>
    <joint name='left_shoulder_pan_joint' type='revolute'>
      <child>left_shoulder_link</child>
      <parent>linear_actuator_link</parent>
      <axis>
        <xyz>-1 -0 -0</xyz>
        <limit>
          <lower>-3.14159</lower>
          <upper>3.14159</upper>
          <effort>18000</effort>
          <velocity>0.69115</velocity>
        </limit>
        <dynamics>
          <damping>0.01</damping>
          <friction>0</friction>
          <spring_reference>0</spring_reference>
          <spring_stiffness>0</spring_stiffness>
        </dynamics>
        <use_parent_model_frame>1</use_parent_model_frame>
      </axis>
    </joint>
    <link name='left_arm_half_1_link'>
      <pose frame=''>0.284495 0.13335 0.75007 -0 0 1.5708</pose>
      <inertial>
        <pose frame=''>0 -0.103563 0 0 -0 0</pose>
        <mass>0.8447</mass>
        <inertia>
          <ixx>0.000435</ixx>
          <ixy>2e-06</ixy>
          <ixz>0.000231</ixz>
          <iyy>0.034947</iyy>
          <iyz>0</iyz>
          <izz>0.035198</izz>
        </inertia>
      </inertial>
      <collision name='left_arm_half_1_link_collision'>
        <pose frame=''>0 0 0 0 -0 0</pose>
        <geometry>
          <mesh>
            <scale>1 1 1</scale>
            <uri>file://MovoRobot/movo_description//meshes/manipulation/jaco/collision/arm_half_1.stl</uri>
          </mesh>
        </geometry>
        <surface>
          <contact>
            <ode>
              <kp>1e+06</kp>
              <kd>100</kd>
              <max_vel>100</max_vel>
              <min_depth>0.001</min_depth>
            </ode>
          </contact>
          <friction>
            <ode>
              <mu>1</mu>
              <mu2>1</mu2>
            </ode>
          </friction>
        </surface>
      </collision>
      <visual name='left_arm_half_1_link_visual'>
        <pose frame=''>0 0 0 0 -0 0</pose>
        <geometry>
          <mesh>
            <scale>1 1 1</scale>
            <uri>file://MovoRobot/movo_description//meshes/manipulation/jaco/visual/arm_half_1.dae</uri>
          </mesh>
        </geometry>
        <material>
          <script>
            <uri>__default__</uri>
            <name>__default__</name>
          </script>
        </material>
      </visual>
      <gravity>1</gravity>
      <velocity_decay/>
      <self_collide>0</self_collide>
    </link>
    <joint name='left_shoulder_lift_joint' type='revolute'>
      <child>left_arm_half_1_link</child>
      <parent>left_shoulder_link</parent>
      <axis>
        <xyz>-0 0 1</xyz>
        <limit>
          <lower>-2.238</lower>
          <upper>2.238</upper>
          <effort>30000.5</effort>
          <velocity>0.69115</velocity>
        </limit>
        <dynamics>
          <damping>0.01</damping>
          <friction>0</friction>
          <spring_reference>0</spring_reference>
          <spring_stiffness>0</spring_stiffness>
        </dynamics>
        <use_parent_model_frame>1</use_parent_model_frame>
      </axis>
    </joint>
    <link name='left_arm_half_2_link'>
      <pose frame=''>0.489495 0.13335 0.75007 -1.5708 0 1.5708</pose>
      <inertial>
        <pose frame=''>0 0 -0.102245 0 -0 0</pose>
        <mass>0.8447</mass>
        <inertia>
          <ixx>0.000435</ixx>
          <ixy>2e-06</ixy>
          <ixz>0.000231</ixz>
          <iyy>0.034947</iyy>
          <iyz>0</iyz>
          <izz>0.035198</izz>
        </inertia>
      </inertial>
      <collision name='left_arm_half_2_link_collision'>
        <pose frame=''>0 0 0 0 -0 0</pose>
        <geometry>
          <mesh>
            <scale>1 1 1</scale>
            <uri>file://MovoRobot/movo_description//meshes/manipulation/jaco/collision/arm_half_2.stl</uri>
          </mesh>
        </geometry>
        <surface>
          <contact>
            <ode>
              <kp>1e+06</kp>
              <kd>100</kd>
              <max_vel>100</max_vel>
              <min_depth>0.001</min_depth>
            </ode>
          </contact>
          <friction>
            <ode>
              <mu>1</mu>
              <mu2>1</mu2>
            </ode>
          </friction>
        </surface>
      </collision>
      <visual name='left_arm_half_2_link_visual'>
        <pose frame=''>0 0 0 0 -0 0</pose>
        <geometry>
          <mesh>
            <scale>1 1 1</scale>
            <uri>file://MovoRobot/movo_description//meshes/manipulation/jaco/visual/arm_half_2.dae</uri>
          </mesh>
        </geometry>
        <material>
          <script>
            <uri>__default__</uri>
            <name>__default__</name>
          </script>
        </material>
      </visual>
      <gravity>1</gravity>
      <velocity_decay/>
      <self_collide>0</self_collide>
    </link>
    <joint name='left_arm_half_joint' type='revolute'>
      <child>left_arm_half_2_link</child>
      <parent>left_arm_half_1_link</parent>
      <axis>
        <xyz>-1 -0 -0</xyz>
        <limit>
          <lower>-3.14159</lower>
          <upper>3.14159</upper>
          <effort>30000.5</effort>
          <velocity>0.69115</velocity>
        </limit>
        <dynamics>
          <damping>0.01</damping>
          <friction>0</friction>
          <spring_reference>0</spring_reference>
          <spring_stiffness>0</spring_stiffness>
        </dynamics>
        <use_parent_model_frame>1</use_parent_model_frame>
      </axis>
    </joint>
    <link name='left_forearm_link'>
      <pose frame=''>0.694495 0.13335 0.75007 -3.14159 0 1.5708</pose>
      <inertial>
        <pose frame=''>0 0.081 -0.0086 0 -0 0</pose>
        <mass>0.674254</mass>
        <inertia>
          <ixx>0.005453</ixx>
          <ixy>3e-06</ixy>
          <ixz>0</ixz>
          <iyy>0.000305</iyy>
          <iyz>8.7e-05</iyz>
          <izz>0.005578</izz>
        </inertia>
      </inertial>
      <collision name='left_forearm_link_collision'>
        <pose frame=''>0 0 0 0 -0 0</pose>
        <geometry>
          <mesh>
            <scale>1 1 1</scale>
            <uri>file://MovoRobot/movo_description//meshes/manipulation/jaco/collision/forearm_7dof.stl</uri>
          </mesh>
        </geometry>
      </collision>
      <visual name='left_forearm_link_visual'>
        <pose frame=''>0 0 0 0 -0 0</pose>
        <geometry>
          <mesh>
            <scale>1 1 1</scale>
            <uri>file://MovoRobot/movo_description//meshes/manipulation/jaco/visual/forearm_7dof.dae</uri>
          </mesh>
        </geometry>
      </visual>
    </link>
    <joint name='left_elbow_joint' type='revolute'>
      <child>left_forearm_link</child>
      <parent>left_arm_half_2_link</parent>
      <axis>
        <xyz>-0 -0 -1</xyz>
        <limit>
          <lower>-2.809</lower>
          <upper>2.809</upper>
          <effort>18000</effort>
          <velocity>0.69115</velocity>
        </limit>
        <dynamics>
          <damping>0.01</damping>
          <friction>0</friction>
          <spring_reference>0</spring_reference>
          <spring_stiffness>0</spring_stiffness>
        </dynamics>
        <use_parent_model_frame>1</use_parent_model_frame>
      </axis>
    </joint>
    <link name='left_wrist_spherical_1_link'>
      <pose frame=''>0.901795 0.13335 0.76147 1.5708 -0 -1.5708</pose>
      <inertial>
        <pose frame=''>0 0.002885 -0.054193 0 -0 0</pose>
        <mass>0.463</mass>
        <inertia>
          <ixx>0.000392</ixx>
          <ixy>0</ixy>
          <ixz>0</ixz>
          <iyy>0.000347</iyy>
          <iyz>0.000101</iyz>
          <izz>0.000233</izz>
        </inertia>
      </inertial>
      <collision name='left_wrist_spherical_1_link_collision'>
        <pose frame=''>0 0 0 0 -0 0</pose>
        <geometry>
          <mesh>
            <scale>1 1 1</scale>
            <uri>file://MovoRobot/movo_description//meshes/manipulation/jaco/collision/wrist_spherical_1.stl</uri>
          </mesh>
        </geometry>
        <surface>
          <contact>
            <ode>
              <kp>1e+06</kp>
              <kd>100</kd>
              <max_vel>100</max_vel>
              <min_depth>0.001</min_depth>
            </ode>
          </contact>
          <friction>
            <ode>
              <mu>1</mu>
              <mu2>1</mu2>
            </ode>
          </friction>
        </surface>
      </collision>
      <visual name='left_wrist_spherical_1_link_visual'>
        <pose frame=''>0 0 0 0 -0 0</pose>
        <geometry>
          <mesh>
            <scale>1 1 1</scale>
            <uri>file://MovoRobot/movo_description//meshes/manipulation/jaco/visual/wrist_spherical_1.dae</uri>
          </mesh>
        </geometry>
        <material>
          <script>
            <uri>__default__</uri>
            <name>__default__</name>
          </script>
        </material>
      </visual>
      <gravity>1</gravity>
      <velocity_decay/>
      <self_collide>0</self_collide>
    </link>
    <joint name='left_wrist_spherical_1_joint' type='revolute'>
      <child>left_wrist_spherical_1_link</child>
      <parent>left_forearm_link</parent>
      <axis>
        <xyz>-1 -0 0</xyz>
        <limit>
          <lower>-3.14159</lower>
          <upper>3.14159</upper>
          <effort>60000.8</effort>
          <velocity>0.921534</velocity>
        </limit>
        <dynamics>
          <damping>0.01</damping>
          <friction>0</friction>
          <spring_reference>0</spring_reference>
          <spring_stiffness>0</spring_stiffness>
        </dynamics>
        <use_parent_model_frame>1</use_parent_model_frame>
      </axis>
    </joint>
    <link name='left_wrist_spherical_2_link'>
      <pose frame=''>1.00554 0.13335 0.76147 -0 -0 -1.5708</pose>
      <inertial>
        <pose frame=''>0 0.049721 -0.002856 0 -0 0</pose>
        <mass>0.463</mass>
        <inertia>
          <ixx>0.000392</ixx>
          <ixy>0</ixy>
          <ixz>0</ixz>
          <iyy>0.000347</iyy>
          <iyz>0.000101</iyz>
          <izz>0.000233</izz>
        </inertia>
      </inertial>
      <collision name='left_wrist_spherical_2_link_collision'>
        <pose frame=''>0 0 0 0 -0 0</pose>
        <geometry>
          <mesh>
            <scale>1 1 1</scale>
            <uri>file://MovoRobot/movo_description//meshes/manipulation/jaco/collision/wrist_spherical_2.stl</uri>
          </mesh>
        </geometry>
        <surface>
          <contact>
            <ode>
              <kp>1e+06</kp>
              <kd>100</kd>
              <max_vel>100</max_vel>
              <min_depth>0.001</min_depth>
            </ode>
          </contact>
          <friction>
            <ode>
              <mu>1</mu>
              <mu2>1</mu2>
            </ode>
          </friction>
        </surface>
      </collision>
      <visual name='left_wrist_spherical_2_link_visual'>
        <pose frame=''>0 0 0 0 -0 0</pose>
        <geometry>
          <mesh>
            <scale>1 1 1</scale>
            <uri>file://MovoRobot/movo_description//meshes/manipulation/jaco/visual/wrist_spherical_2.dae</uri>
          </mesh>
        </geometry>
        <material>
          <script>
            <uri>__default__</uri>
            <name>__default__</name>
          </script>
        </material>
      </visual>
      <gravity>1</gravity>
      <velocity_decay/>
      <self_collide>0</self_collide>
    </link>
    <joint name='left_wrist_spherical_2_joint' type='revolute'>
      <child>left_wrist_spherical_2_link</child>
      <parent>left_wrist_spherical_1_link</parent>
      <axis>
        <xyz>0 0 1</xyz>
        <limit>
          <lower>-2.78</lower>
          <upper>2.78</upper>
          <effort>60000.8</effort>
          <velocity>0.921534</velocity>
        </limit>
        <dynamics>
          <damping>0.01</damping>
          <friction>0</friction>
          <spring_reference>0</spring_reference>
          <spring_stiffness>0</spring_stiffness>
        </dynamics>
        <use_parent_model_frame>1</use_parent_model_frame>
      </axis>
    </joint>
    <link name='left_wrist_3_link'>
      <pose frame=''>1.10929 0.13335 0.76147 -1.5708 0 1.5708</pose>
      <inertial>
        <pose frame=''>-0.000152 -0.004169 -0.09596 0 -0 0</pose>
        <mass>0.990094</mass>
        <inertia>
          <ixx>0.00425431</ixx>
          <ixy>6.65278e-07</ixy>
          <ixz>-1.49586e-05</ixz>
          <iyy>0.00411121</iyy>
          <iyz>0.000122735</iyz>
          <izz>0.000899307</izz>
        </inertia>
      </inertial>
      <collision name='left_wrist_3_link_collision'>
        <pose frame=''>0 0 0 0 -0 0</pose>
        <geometry>
          <mesh>
            <scale>1 1 1</scale>
            <uri>file://MovoRobot/movo_description//meshes/manipulation/jaco/collision/kinova_actuator_gearing.stl</uri>
          </mesh>
        </geometry>
        <surface>
          <contact>
            <ode>
              <kp>1e+06</kp>
              <kd>100</kd>
              <max_vel>100</max_vel>
              <min_depth>0.001</min_depth>
            </ode>
          </contact>
          <friction>
            <ode>
              <mu>1</mu>
              <mu2>1</mu2>
            </ode>
          </friction>
        </surface>
      </collision>
      <collision name='left_wrist_3_link_fixed_joint_lump__left_gripper_base_link_collision_1'>
        <pose frame=''>-0 0 0 0 -0 0</pose>
        <geometry>
          <mesh>
            <scale>1 1 1</scale>
            <uri>file://MovoRobot/movo_description//meshes/manipulation/kinova_grippers/collision/kg3_base_link.stl</uri>
          </mesh>
        </geometry>
        <surface>
          <contact>
            <ode>
              <kp>1e+06</kp>
              <kd>1</kd>
              <max_vel>0</max_vel>
              <min_depth>0.0001</min_depth>
            </ode>
          </contact>
          <friction>
            <ode>
              <mu>0.8</mu>
              <mu2>0.8</mu2>
            </ode>
          </friction>
        </surface>
      </collision>
      <visual name='left_wrist_3_link_visual'>
        <pose frame=''>0 0 0 0 -0 0</pose>
        <geometry>
          <mesh>
            <scale>1 1 1</scale>
            <uri>file://MovoRobot/movo_description//meshes/manipulation/jaco/visual/kinova_actuator_gearing.dae</uri>
          </mesh>
        </geometry>
        <material>
          <script>
            <uri>__default__</uri>
            <name>__default__</name>
          </script>
        </material>
      </visual>
      <visual name='left_wrist_3_link_fixed_joint_lump__left_gripper_base_link_visual_1'>
        <pose frame=''>-0 0 0 0 -0 0</pose>
        <geometry>
          <mesh>
            <scale>1 1 1</scale>
            <uri>file://MovoRobot/movo_description//meshes/manipulation/kinova_grippers/visual/kg3_base_link.dae</uri>
          </mesh>
        </geometry>
        <material>
          <script>
            <uri>__default__</uri>
            <name>__default__</name>
          </script>
        </material>
      </visual>
      <velocity_decay/>
      <gravity>1</gravity>
      <velocity_decay/>
      <self_collide>0</self_collide>
    </link>
    <joint name='left_wrist_3_joint' type='revolute'>
      <child>left_wrist_3_link</child>
      <parent>left_wrist_spherical_2_link</parent>
      <axis>
        <xyz>-1 -0 -0</xyz>
        <limit>
          <lower>-3.14159</lower>
          <upper>3.14159</upper>
          <effort>60000.8</effort>
          <velocity>0.921534</velocity>
        </limit>
        <dynamics>
          <damping>0.01</damping>
          <friction>0</friction>
          <spring_reference>0</spring_reference>
          <spring_stiffness>0</spring_stiffness>
        </dynamics>
        <use_parent_model_frame>1</use_parent_model_frame>
      </axis>
    </joint>
    <link name='left_gripper_finger1_knuckle_link'>
      <pose frame=''>1.22393 0.130555 0.730152 3.08956 -1.39126 -1.62279</pose>
      <inertial>
        <pose frame=''>-0.028253 -0.032416 0 0 -0 0</pose>
        <mass>0.021817</mass>
        <inertia>
          <ixx>9.39482e-06</ixx>
          <ixy>-1.3461e-06</ixy>
          <ixz>0</ixz>
          <iyy>4.07539e-06</iyy>
          <iyz>0</iyz>
          <izz>1.14702e-05</izz>
        </inertia>
      </inertial>
      <collision name='left_gripper_finger1_knuckle_link_collision'>
        <pose frame=''>0 0 0 0 -0 0</pose>
        <geometry>
          <mesh>
            <scale>1 1 1</scale>
            <uri>file://MovoRobot/movo_description//meshes/manipulation/kinova_grippers/collision/finger_knuckle.stl</uri>
          </mesh>
        </geometry>
        <surface>
          <contact>
            <ode>
              <kp>1e+06</kp>
              <kd>1</kd>
              <max_vel>0</max_vel>
              <min_depth>0.0001</min_depth>
            </ode>
          </contact>
          <friction>
            <ode>
              <mu>0.8</mu>
              <mu2>0.8</mu2>
            </ode>
          </friction>
        </surface>
      </collision>
      <collision name='left_gripper_finger1_knuckle_link_fixed_joint_lump__left_gripper_finger1_finger_tip_link_collision_1'>
        <pose frame=''>-0.024598 -0.036051 0 0 -0 0</pose>
        <geometry>
          <mesh>
            <scale>1 1 1</scale>
            <uri>file://MovoRobot/movo_description//meshes/manipulation/kinova_grippers/collision/finger_tip.stl</uri>
          </mesh>
        </geometry>
        <surface>
          <contact>
            <ode>
              <kp>1e+06</kp>
              <kd>1</kd>
              <max_vel>0</max_vel>
              <min_depth>0.0001</min_depth>
            </ode>
          </contact>
          <friction>
            <ode>
              <mu>0.8</mu>
              <mu2>0.8</mu2>
            </ode>
          </friction>
        </surface>
      </collision>
      <visual name='left_gripper_finger1_knuckle_link_visual'>
        <pose frame=''>0 0 0 0 -0 0</pose>
        <geometry>
          <mesh>
            <scale>1 1 1</scale>
            <uri>file://MovoRobot/movo_description//meshes/manipulation/kinova_grippers/visual/finger_knuckle.dae</uri>
          </mesh>
        </geometry>
        <material>
          <script>
            <uri>__default__</uri>
            <name>__default__</name>
          </script>
        </material>
      </visual>
      <visual name='left_gripper_finger1_knuckle_link_fixed_joint_lump__left_gripper_finger1_finger_tip_link_visual_1'>
        <pose frame=''>-0.024598 -0.036051 0 0 -0 0</pose>
        <geometry>
          <mesh>
            <scale>1 1 1</scale>
            <uri>file://MovoRobot/movo_description//meshes/manipulation/kinova_grippers/visual/finger_tip.dae</uri>
          </mesh>
        </geometry>
        <material>
          <script>
            <uri>__default__</uri>
            <name>__default__</name>
          </script>
        </material>
      </visual>
      <velocity_decay/>
      <gravity>1</gravity>
      <velocity_decay/>
      <self_collide>0</self_collide>
    </link>
    <joint name='left_gripper_finger1_joint' type='revolute'>
      <child>left_gripper_finger1_knuckle_link</child>
      <parent>left_wrist_3_link</parent>
      <axis>
        <xyz>-0.103009 -0.978563 -0.178336</xyz>
        <limit>
          <lower>0</lower>
          <upper>0.986111</upper>
          <effort>3</effort>
          <velocity>1</velocity>
        </limit>
        <dynamics>
          <spring_reference>0</spring_reference>
          <spring_stiffness>0</spring_stiffness>
        </dynamics>
        <use_parent_model_frame>1</use_parent_model_frame>
      </axis>
    </joint>
    <link name='left_gripper_finger2_knuckle_link'>
      <pose frame=''>1.224 0.155639 0.788723 3.14159 1.38609 -1.5708</pose>
      <inertial>
        <pose frame=''>-0.028253 -0.032416 0 0 -0 0</pose>
        <mass>0.021817</mass>
        <inertia>
          <ixx>9.39482e-06</ixx>
          <ixy>-1.3461e-06</ixy>
          <ixz>0</ixz>
          <iyy>4.07539e-06</iyy>
          <iyz>0</iyz>
          <izz>1.14702e-05</izz>
        </inertia>
      </inertial>
      <collision name='left_gripper_finger2_knuckle_link_collision'>
        <pose frame=''>0 0 0 0 -0 0</pose>
        <geometry>
          <mesh>
            <scale>1 1 1</scale>
            <uri>file://MovoRobot/movo_description//meshes/manipulation/kinova_grippers/collision/finger_knuckle.stl</uri>
          </mesh>
        </geometry>
        <surface>
          <contact>
            <ode>
              <kp>1e+06</kp>
              <kd>1</kd>
              <max_vel>0</max_vel>
              <min_depth>0.0001</min_depth>
            </ode>
          </contact>
          <friction>
            <ode>
              <mu>0.8</mu>
              <mu2>0.8</mu2>
            </ode>
          </friction>
        </surface>
      </collision>
      <collision name='left_gripper_finger2_knuckle_link_fixed_joint_lump__left_gripper_finger2_finger_tip_link_collision_1'>
        <pose frame=''>-0.024598 -0.036051 0 0 -0 0</pose>
        <geometry>
          <mesh>
            <scale>1 1 1</scale>
            <uri>file://MovoRobot/movo_description//meshes/manipulation/kinova_grippers/collision/finger_tip.stl</uri>
          </mesh>
        </geometry>
        <surface>
          <contact>
            <ode>
              <kp>1e+06</kp>
              <kd>1</kd>
              <max_vel>0</max_vel>
              <min_depth>0.0001</min_depth>
            </ode>
          </contact>
          <friction>
            <ode>
              <mu>0.8</mu>
              <mu2>0.8</mu2>
            </ode>
          </friction>
        </surface>
      </collision>
      <visual name='left_gripper_finger2_knuckle_link_visual'>
        <pose frame=''>0 0 0 0 -0 0</pose>
        <geometry>
          <mesh>
            <scale>1 1 1</scale>
            <uri>file://MovoRobot/movo_description//meshes/manipulation/kinova_grippers/visual/finger_knuckle.dae</uri>
          </mesh>
        </geometry>
        <material>
          <script>
            <uri>__default__</uri>
            <name>__default__</name>
          </script>
        </material>
      </visual>
      <visual name='left_gripper_finger2_knuckle_link_fixed_joint_lump__left_gripper_finger2_finger_tip_link_visual_1'>
        <pose frame=''>-0.024598 -0.036051 0 0 -0 0</pose>
        <geometry>
          <mesh>
            <scale>1 1 1</scale>
            <uri>file://MovoRobot/movo_description//meshes/manipulation/kinova_grippers/visual/finger_tip.dae</uri>
          </mesh>
        </geometry>
        <material>
          <script>
            <uri>__default__</uri>
            <name>__default__</name>
          </script>
        </material>
      </visual>
      <velocity_decay/>
      <gravity>1</gravity>
      <velocity_decay/>
      <self_collide>0</self_collide>
    </link>
    <joint name='left_gripper_finger2_joint' type='revolute'>
      <child>left_gripper_finger2_knuckle_link</child>
      <parent>left_wrist_3_link</parent>
      <axis>
        <xyz>-0 0.982991 -0.183655</xyz>
        <limit>
          <lower>0</lower>
          <upper>0.986111</upper>
          <effort>3</effort>
          <velocity>1</velocity>
        </limit>
        <dynamics>
          <spring_reference>0</spring_reference>
          <spring_stiffness>0</spring_stiffness>
        </dynamics>
        <use_parent_model_frame>1</use_parent_model_frame>
      </axis>
    </joint>
    <link name='left_gripper_finger3_knuckle_link'>
      <pose frame=''>1.22402 0.111066 0.788693 0 1.3861 1.5708</pose>
      <inertial>
        <pose frame=''>-0.028253 -0.032416 0 0 -0 0</pose>
        <mass>0.021817</mass>
        <inertia>
          <ixx>9.39482e-06</ixx>
          <ixy>-1.3461e-06</ixy>
          <ixz>0</ixz>
          <iyy>4.07539e-06</iyy>
          <iyz>0</iyz>
          <izz>1.14702e-05</izz>
        </inertia>
      </inertial>
      <collision name='left_gripper_finger3_knuckle_link_collision'>
        <pose frame=''>0 0 0 0 -0 0</pose>
        <geometry>
          <mesh>
            <scale>1 1 1</scale>
            <uri>file://MovoRobot/movo_description//meshes/manipulation/kinova_grippers/collision/finger_knuckle.stl</uri>
          </mesh>
        </geometry>
        <surface>
          <contact>
            <ode>
              <kp>1e+06</kp>
              <kd>1</kd>
              <max_vel>0</max_vel>
              <min_depth>0.0001</min_depth>
            </ode>
          </contact>
          <friction>
            <ode>
              <mu>0.8</mu>
              <mu2>0.8</mu2>
            </ode>
          </friction>
        </surface>
      </collision>
      <collision name='left_gripper_finger3_knuckle_link_fixed_joint_lump__left_gripper_finger3_finger_tip_link_collision_1'>
        <pose frame=''>-0.024598 -0.036051 0 0 -0 0</pose>
        <geometry>
          <mesh>
            <scale>1 1 1</scale>
            <uri>file://MovoRobot/movo_description//meshes/manipulation/kinova_grippers/collision/finger_tip.stl</uri>
          </mesh>
        </geometry>
        <surface>
          <contact>
            <ode>
              <kp>1e+06</kp>
              <kd>1</kd>
              <max_vel>0</max_vel>
              <min_depth>0.0001</min_depth>
            </ode>
          </contact>
          <friction>
            <ode>
              <mu>0.8</mu>
              <mu2>0.8</mu2>
            </ode>
          </friction>
        </surface>
      </collision>
      <visual name='left_gripper_finger3_knuckle_link_visual'>
        <pose frame=''>0 0 0 0 -0 0</pose>
        <geometry>
          <mesh>
            <scale>1 1 1</scale>
            <uri>file://MovoRobot/movo_description//meshes/manipulation/kinova_grippers/visual/finger_knuckle.dae</uri>
          </mesh>
        </geometry>
        <material>
          <script>
            <uri>__default__</uri>
            <name>__default__</name>
          </script>
        </material>
      </visual>
      <visual name='left_gripper_finger3_knuckle_link_fixed_joint_lump__left_gripper_finger3_finger_tip_link_visual_1'>
        <pose frame=''>-0.024598 -0.036051 0 0 -0 0</pose>
        <geometry>
          <mesh>
            <scale>1 1 1</scale>
            <uri>file://MovoRobot/movo_description//meshes/manipulation/kinova_grippers/visual/finger_tip.dae</uri>
          </mesh>
        </geometry>
        <material>
          <script>
            <uri>__default__</uri>
            <name>__default__</name>
          </script>
        </material>
      </visual>
      <velocity_decay/>
      <gravity>1</gravity>
      <velocity_decay/>
      <self_collide>0</self_collide>
    </link>
    <joint name='left_gripper_finger3_joint' type='revolute'>
      <child>left_gripper_finger3_knuckle_link</child>
      <parent>left_wrist_3_link</parent>
      <axis>
        <xyz>-0 0.982992 0.183648</xyz>
        <limit>
          <lower>0</lower>
          <upper>0.986111</upper>
          <effort>3</effort>
          <velocity>1</velocity>
        </limit>
        <dynamics>
          <spring_reference>0</spring_reference>
          <spring_stiffness>0</spring_stiffness>
        </dynamics>
        <use_parent_model_frame>1</use_parent_model_frame>
      </axis>
    </joint> -->
    <link name='pan_link'>
      <pose frame=''>0.27449 0 0.870315 3.14159 -0 0</pose>
      <inertial>
        <pose frame=''>-3.6e-05 0.021015 -0.052191 0 -0 0</pose>
        <mass>0.470548</mass>
        <inertia>
          <ixx>0.000957</ixx>
          <ixy>0</ixy>
          <ixz>0</ixz>
          <iyy>0.000805</iyy>
          <iyz>-0.000328</iyz>
          <izz>0.000353</izz>
        </inertia>
      </inertial>
      <collision name='pan_link_collision'>
        <pose frame=''>0 0 0 0 -0 0</pose>
        <geometry>
          <mesh>
            <scale>1 1 1</scale>
            <uri>file://MovoRobot/movo_description//meshes/pan_tilt/collision/pan_link.stl</uri>
          </mesh>
        </geometry>
      </collision>
      <visual name='pan_link_visual'>
        <pose frame=''>0 0 0 0 -0 0</pose>
        <geometry>
          <mesh>
            <scale>1 1 1</scale>
            <uri>file://MovoRobot/movo_description//meshes/pan_tilt/visual/pan_link.dae</uri>
          </mesh>
        </geometry>
      </visual>
    </link>
    <joint name='pan_joint' type='revolute'>
      <child>pan_link</child>
      <parent>linear_actuator_link</parent>
      <axis>
        <xyz>0 -3e-06 -1</xyz>
        <limit>
          <lower>-1.5708</lower>
          <upper>1.5708</upper>
          <effort>7</effort>
          <velocity>0.907571</velocity>
        </limit>
        <dynamics>
          <spring_reference>0</spring_reference>
          <spring_stiffness>0</spring_stiffness>
        </dynamics>
        <use_parent_model_frame>1</use_parent_model_frame>
      </axis>
    </joint>
    <link name='tilt_link'>
      <pose frame=''>0.27449 -0.026 0.961065 0.463649 -1.57079 1.10715</pose>
      <inertial>
        <pose frame=''>0.013478 -0.00669 -0.040467 0 -0 0</pose>
        <mass>1.83451</mass>
        <inertia>
          <ixx>0.00777963</ixx>
          <ixy>-5.63296e-05</ixy>
          <ixz>-0.000358143</ixz>
          <iyy>0.00239627</iyy>
          <iyz>-0.00019448</iyz>
          <izz>0.00257745</izz>
        </inertia>
      </inertial>
      <collision name='tilt_link_collision'>
        <pose frame=''>0 0 0 0 -0 0</pose>
        <geometry>
          <mesh>
            <scale>1 1 1</scale>
            <uri>file://MovoRobot/movo_description//meshes/pan_tilt/collision/tilt_link.stl</uri>
          </mesh>
        </geometry>
      </collision>
      <collision name='tilt_link_fixed_joint_lump__kinect2_link_collision_1'>
        <pose frame=''>0.05825 -0.010588 -0.026 -1.57079 -0 -1.57079</pose>
        <geometry>
          <mesh>
            <scale>1 1 1</scale>
            <uri>file://MovoRobot/movo_description//meshes/sensors/collision/kinect_one_collision.stl</uri>
          </mesh>
        </geometry>
      </collision>
      <visual name='tilt_link_visual'>
        <pose frame=''>0 0 0 0 -0 0</pose>
        <geometry>
          <mesh>
            <scale>1 1 1</scale>
            <uri>file://MovoRobot/movo_description//meshes/pan_tilt/visual/tilt_link.dae</uri>
          </mesh>
        </geometry>
      </visual>
      <visual name='tilt_link_fixed_joint_lump__kinect2_link_visual_1'>
        <pose frame=''>0.05825 -0.010588 -0.026 -1.57079 -0 -1.57079</pose>
        <geometry>
          <mesh>
            <scale>1 1 1</scale>
            <uri>file://MovoRobot/movo_description//meshes/sensors/visual/kinect_one.dae</uri>
          </mesh>
        </geometry>
      </visual>
      <gravity>1</gravity>
      <velocity_decay/>
      <self_collide>0</self_collide>
      <!--sensor name='kinect2_ir_sensor' type='depth'>
        <always_on>1</always_on>
        <update_rate>30</update_rate>
        <camera name='__default__'>
          <horizontal_fov>1.22173</horizontal_fov>
          <image>
            <format>L8</format>
            <width>512</width>
            <height>424</height>
          </image>
          <clip>
            <near>0.01</near>
            <far>100</far>
          </clip>
        </camera>
        <plugin name='kinect2_ir_link_controller' filename='libgazebo_ros_openni_kinect.so'>
          <baseline>0.2</baseline>
          <alwaysOn>true</alwaysOn>
          <updateRate>1.0</updateRate>
          <cameraName>kinect2/sd/image_ir</cameraName>
          <imageTopicName>/kinect2/sd/image_ir</imageTopicName>
          <cameraInfoTopicName>/kinect2/sd/camera_info</cameraInfoTopicName>
          <depthImageTopicName>/kinect2/sd/image_depth</depthImageTopicName>
          <depthImageCameraInfoTopicName>/kinect2/sd/depth/camera_info</depthImageCameraInfoTopicName>
          <pointCloudTopicName>/kinect2/sd/points</pointCloudTopicName>
          <frameName>kinect2_ir_optical_frame</frameName>
          <pointCloudCutoff>0.1</pointCloudCutoff>
          <pointCloudCutoffMax>12.0</pointCloudCutoffMax>
          <distortionK1>0.0</distortionK1>
          <distortionK2>0.0</distortionK2>
          <distortionK3>0.0</distortionK3>
          <distortionT1>0.0</distortionT1>
          <distortionT2>0.0</distortionT2>
          <CxPrime>0</CxPrime>
          <Cx>0</Cx>
          <Cy>0</Cy>
          <focalLength>0</focalLength>
          <hackBaseline>0</hackBaseline>
        </plugin>
        <pose frame=''>0.10026 -0.035087 0.00725 -1.57079 -0 -1.57079</pose>
      </sensor-->
    </link>
    <joint name='tilt_joint' type='revolute'>
      <child>tilt_link</child>
      <parent>pan_link</parent>
      <axis>
        <xyz>1e-06 -1 3e-06</xyz>
        <limit>
          <lower>-1.5708</lower>
          <upper>1.5708</upper>
          <effort>7</effort>
          <velocity>0.907571</velocity>
        </limit>
        <dynamics>
          <spring_reference>0</spring_reference>
          <spring_stiffness>0</spring_stiffness>
        </dynamics>
        <use_parent_model_frame>1</use_parent_model_frame>
      </axis>
    </joint>
    <link name='right_shoulder_link'>
      <pose frame=''>0.165745 -0.13335 0.75007 -1.5708 0 1.5708</pose>
      <inertial>
        <pose frame=''>1.8e-05 -0.004667 -0.060609 0 -0 0</pose>
        <mass>0.824524</mass>
        <inertia>
          <ixx>0.002561</ixx>
          <ixy>0</ixy>
          <ixz>1e-06</ixz>
          <iyy>0.002653</iyy>
          <iyz>0.000212</iyz>
          <izz>0.000524</izz>
        </inertia>
      </inertial>
      <collision name='right_shoulder_link_collision'>
        <pose frame=''>0 0 0 0 -0 0</pose>
        <geometry>
          <mesh>
            <scale>1 1 1</scale>
            <uri>file://MovoRobot/movo_description//meshes/manipulation/jaco/collision/shoulder_7dof.stl</uri>
          </mesh>
        </geometry>
        <surface>
          <contact>
            <ode>
              <kp>1e+06</kp>
              <kd>100</kd>
              <max_vel>100</max_vel>
              <min_depth>0.001</min_depth>
            </ode>
          </contact>
          <friction>
            <ode>
              <mu>1</mu>
              <mu2>1</mu2>
            </ode>
          </friction>
        </surface>
      </collision>
      <visual name='right_shoulder_link_visual'>
        <pose frame=''>0 0 0 0 -0 0</pose>
        <geometry>
          <mesh>
            <scale>1 1 1</scale>
            <uri>file://MovoRobot/movo_description//meshes/manipulation/jaco/visual/shoulder_7dof.dae</uri>
          </mesh>
        </geometry>
        <material>
          <script>
            <uri>__default__</uri>
            <name>__default__</name>
          </script>
        </material>
      </visual>
      <gravity>1</gravity>
      <velocity_decay/>
      <self_collide>0</self_collide>
    </link>
    <joint name='right_shoulder_pan_joint' type='revolute'>
      <child>right_shoulder_link</child>
      <parent>linear_actuator_link</parent>
      <axis>
        <xyz>-1 -0 -0</xyz>
        <limit>
          <lower>-3.14159</lower>
          <upper>3.14159</upper>
          <effort>18000</effort>
          <velocity>0.69115</velocity>
        </limit>
        <dynamics>
          <damping>0.01</damping>
          <friction>0</friction>
          <spring_reference>0</spring_reference>
          <spring_stiffness>0</spring_stiffness>
        </dynamics>
        <use_parent_model_frame>1</use_parent_model_frame>
      </axis>
    </joint>
    <link name='right_arm_half_1_link'>
      <pose frame=''>0.284495 -0.13335 0.75007 -0 0 1.5708</pose>
      <inertial>
        <pose frame=''>0 -0.103563 0 0 -0 0</pose>
        <mass>0.8447</mass>
        <inertia>
          <ixx>0.000435</ixx>
          <ixy>2e-06</ixy>
          <ixz>0.000231</ixz>
          <iyy>0.034947</iyy>
          <iyz>0</iyz>
          <izz>0.035198</izz>
        </inertia>
      </inertial>
      <collision name='right_arm_half_1_link_collision'>
        <pose frame=''>0 0 0 0 -0 0</pose>
        <geometry>
          <mesh>
            <scale>1 1 1</scale>
            <uri>file://MovoRobot/movo_description//meshes/manipulation/jaco/collision/arm_half_1.stl</uri>
          </mesh>
        </geometry>
        <surface>
          <contact>
            <ode>
              <kp>1e+06</kp>
              <kd>100</kd>
              <max_vel>100</max_vel>
              <min_depth>0.001</min_depth>
            </ode>
          </contact>
          <friction>
            <ode>
              <mu>1</mu>
              <mu2>1</mu2>
            </ode>
          </friction>
        </surface>
      </collision>
      <visual name='right_arm_half_1_link_visual'>
        <pose frame=''>0 0 0 0 -0 0</pose>
        <geometry>
          <mesh>
            <scale>1 1 1</scale>
            <uri>file://MovoRobot/movo_description//meshes/manipulation/jaco/visual/arm_half_1.dae</uri>
          </mesh>
        </geometry>
        <material>
          <script>
            <uri>__default__</uri>
            <name>__default__</name>
          </script>
        </material>
      </visual>
      <gravity>1</gravity>
      <velocity_decay/>
      <self_collide>0</self_collide>
    </link>
    <joint name='right_shoulder_lift_joint' type='revolute'>
      <child>right_arm_half_1_link</child>
      <parent>right_shoulder_link</parent>
      <axis>
        <xyz>-0 0 1</xyz>
        <limit>
          <lower>-2.238</lower>
          <upper>2.238</upper>
          <effort>30000.5</effort>
          <velocity>0.69115</velocity>
        </limit>
        <dynamics>
          <damping>0.01</damping>
          <friction>0</friction>
          <spring_reference>0</spring_reference>
          <spring_stiffness>0</spring_stiffness>
        </dynamics>
        <use_parent_model_frame>1</use_parent_model_frame>
      </axis>
    </joint>
    <link name='right_arm_half_2_link'>
      <pose frame=''>0.489495 -0.13335 0.75007 -1.5708 0 1.5708</pose>
      <inertial>
        <pose frame=''>0 0 -0.102245 0 -0 0</pose>
        <mass>0.8447</mass>
        <inertia>
          <ixx>0.000435</ixx>
          <ixy>2e-06</ixy>
          <ixz>0.000231</ixz>
          <iyy>0.034947</iyy>
          <iyz>0</iyz>
          <izz>0.035198</izz>
        </inertia>
      </inertial>
      <collision name='right_arm_half_2_link_collision'>
        <pose frame=''>0 0 0 0 -0 0</pose>
        <geometry>
          <mesh>
            <scale>1 1 1</scale>
            <uri>file://MovoRobot/movo_description//meshes/manipulation/jaco/collision/arm_half_2.stl</uri>
          </mesh>
        </geometry>
        <surface>
          <contact>
            <ode>
              <kp>1e+06</kp>
              <kd>100</kd>
              <max_vel>100</max_vel>
              <min_depth>0.001</min_depth>
            </ode>
          </contact>
          <friction>
            <ode>
              <mu>1</mu>
              <mu2>1</mu2>
            </ode>
          </friction>
        </surface>
      </collision>
      <visual name='right_arm_half_2_link_visual'>
        <pose frame=''>0 0 0 0 -0 0</pose>
        <geometry>
          <mesh>
            <scale>1 1 1</scale>
            <uri>file://MovoRobot/movo_description//meshes/manipulation/jaco/visual/arm_half_2.dae</uri>
          </mesh>
        </geometry>
        <material>
          <script>
            <uri>__default__</uri>
            <name>__default__</name>
          </script>
        </material>
      </visual>
      <gravity>1</gravity>
      <velocity_decay/>
      <self_collide>0</self_collide>
    </link>
    <joint name='right_arm_half_joint' type='revolute'>
      <child>right_arm_half_2_link</child>
      <parent>right_arm_half_1_link</parent>
      <axis>
        <xyz>-1 -0 -0</xyz>
        <limit>
          <lower>-3.14159</lower>
          <upper>3.14159</upper>
          <effort>30000.5</effort>
          <velocity>0.69115</velocity>
        </limit>
        <dynamics>
          <damping>0.01</damping>
          <friction>0</friction>
          <spring_reference>0</spring_reference>
          <spring_stiffness>0</spring_stiffness>
        </dynamics>
        <use_parent_model_frame>1</use_parent_model_frame>
      </axis>
    </joint>
    <link name='right_forearm_link'>
      <pose frame=''>0.694495 -0.13335 0.75007 -3.14159 0 1.5708</pose>
      <inertial>
        <pose frame=''>0 0.081 -0.0086 0 -0 0</pose>
        <mass>0.674254</mass>
        <inertia>
          <ixx>0.005453</ixx>
          <ixy>3e-06</ixy>
          <ixz>0</ixz>
          <iyy>0.000305</iyy>
          <iyz>8.7e-05</iyz>
          <izz>0.005578</izz>
        </inertia>
      </inertial>
      <collision name='right_forearm_link_collision'>
        <pose frame=''>0 0 0 0 -0 0</pose>
        <geometry>
          <mesh>
            <scale>1 1 1</scale>
            <uri>file://MovoRobot/movo_description//meshes/manipulation/jaco/collision/forearm_7dof.stl</uri>
          </mesh>
        </geometry>
      </collision>
      <visual name='right_forearm_link_visual'>
        <pose frame=''>0 0 0 0 -0 0</pose>
        <geometry>
          <mesh>
            <scale>1 1 1</scale>
            <uri>file://MovoRobot/movo_description//meshes/manipulation/jaco/visual/forearm_7dof.dae</uri>
          </mesh>
        </geometry>
      </visual>
    </link>
    <joint name='right_elbow_joint' type='revolute'>
      <child>right_forearm_link</child>
      <parent>right_arm_half_2_link</parent>
      <axis>
        <xyz>-0 -0 -1</xyz>
        <limit>
          <lower>-2.809</lower>
          <upper>2.809</upper>
          <effort>18000</effort>
          <velocity>0.69115</velocity>
        </limit>
        <dynamics>
          <damping>0.01</damping>
          <friction>0</friction>
          <spring_reference>0</spring_reference>
          <spring_stiffness>0</spring_stiffness>
        </dynamics>
        <use_parent_model_frame>1</use_parent_model_frame>
      </axis>
    </joint>
    <link name='right_wrist_spherical_1_link'>
      <pose frame=''>0.901795 -0.13335 0.76147 1.5708 -0 -1.5708</pose>
      <inertial>
        <pose frame=''>0 0.002885 -0.054193 0 -0 0</pose>
        <mass>0.463</mass>
        <inertia>
          <ixx>0.000392</ixx>
          <ixy>0</ixy>
          <ixz>0</ixz>
          <iyy>0.000347</iyy>
          <iyz>0.000101</iyz>
          <izz>0.000233</izz>
        </inertia>
      </inertial>
      <collision name='right_wrist_spherical_1_link_collision'>
        <pose frame=''>0 0 0 0 -0 0</pose>
        <geometry>
          <mesh>
            <scale>1 1 1</scale>
            <uri>file://MovoRobot/movo_description//meshes/manipulation/jaco/collision/wrist_spherical_1.stl</uri>
          </mesh>
        </geometry>
        <surface>
          <contact>
            <ode>
              <kp>1e+06</kp>
              <kd>100</kd>
              <max_vel>100</max_vel>
              <min_depth>0.001</min_depth>
            </ode>
          </contact>
          <friction>
            <ode>
              <mu>1</mu>
              <mu2>1</mu2>
            </ode>
          </friction>
        </surface>
      </collision>
      <visual name='right_wrist_spherical_1_link_visual'>
        <pose frame=''>0 0 0 0 -0 0</pose>
        <geometry>
          <mesh>
            <scale>1 1 1</scale>
            <uri>file://MovoRobot/movo_description//meshes/manipulation/jaco/visual/wrist_spherical_1.dae</uri>
          </mesh>
        </geometry>
        <material>
          <script>
            <uri>__default__</uri>
            <name>__default__</name>
          </script>
        </material>
      </visual>
      <gravity>1</gravity>
      <velocity_decay/>
      <self_collide>0</self_collide>
    </link>
    <joint name='right_wrist_spherical_1_joint' type='revolute'>
      <child>right_wrist_spherical_1_link</child>
      <parent>right_forearm_link</parent>
      <axis>
        <xyz>-1 -0 0</xyz>
        <limit>
          <lower>-3.14159</lower>
          <upper>3.14159</upper>
          <effort>60000.8</effort>
          <velocity>0.921534</velocity>
        </limit>
        <dynamics>
          <damping>0.01</damping>
          <friction>0</friction>
          <spring_reference>0</spring_reference>
          <spring_stiffness>0</spring_stiffness>
        </dynamics>
        <use_parent_model_frame>1</use_parent_model_frame>
      </axis>
    </joint>
    <link name='right_wrist_spherical_2_link'>
      <pose frame=''>1.00554 -0.13335 0.76147 -0 -0 -1.5708</pose>
      <inertial>
        <pose frame=''>0 0.049721 -0.002856 0 -0 0</pose>
        <mass>0.463</mass>
        <inertia>
          <ixx>0.000392</ixx>
          <ixy>0</ixy>
          <ixz>0</ixz>
          <iyy>0.000347</iyy>
          <iyz>0.000101</iyz>
          <izz>0.000233</izz>
        </inertia>
      </inertial>
      <collision name='right_wrist_spherical_2_link_collision'>
        <pose frame=''>0 0 0 0 -0 0</pose>
        <geometry>
          <mesh>
            <scale>1 1 1</scale>
            <uri>file://MovoRobot/movo_description//meshes/manipulation/jaco/collision/wrist_spherical_2.stl</uri>
          </mesh>
        </geometry>
        <surface>
          <contact>
            <ode>
              <kp>1e+06</kp>
              <kd>100</kd>
              <max_vel>100</max_vel>
              <min_depth>0.001</min_depth>
            </ode>
          </contact>
          <friction>
            <ode>
              <mu>1</mu>
              <mu2>1</mu2>
            </ode>
          </friction>
        </surface>
      </collision>
      <visual name='right_wrist_spherical_2_link_visual'>
        <pose frame=''>0 0 0 0 -0 0</pose>
        <geometry>
          <mesh>
            <scale>1 1 1</scale>
            <uri>file://MovoRobot/movo_description//meshes/manipulation/jaco/visual/wrist_spherical_2.dae</uri>
          </mesh>
        </geometry>
        <material>
          <script>
            <uri>__default__</uri>
            <name>__default__</name>
          </script>
        </material>
      </visual>
      <gravity>1</gravity>
      <velocity_decay/>
      <self_collide>0</self_collide>
    </link>
    <joint name='right_wrist_spherical_2_joint' type='revolute'>
      <child>right_wrist_spherical_2_link</child>
      <parent>right_wrist_spherical_1_link</parent>
      <axis>
        <xyz>0 0 1</xyz>
        <limit>
          <lower>-2.78</lower>
          <upper>2.78</upper>
          <effort>60000.8</effort>
          <velocity>0.921534</velocity>
        </limit>
        <dynamics>
          <damping>0.01</damping>
          <friction>0</friction>
          <spring_reference>0</spring_reference>
          <spring_stiffness>0</spring_stiffness>
        </dynamics>
        <use_parent_model_frame>1</use_parent_model_frame>
      </axis>
    </joint>
    <link name='right_wrist_3_link'>
      <pose frame=''>1.10929 -0.13335 0.76147 -1.5708 0 1.5708</pose>
      <inertial>
        <pose frame=''>-0.000152 -0.004169 -0.09596 0 -0 0</pose>
        <mass>0.990094</mass>
        <inertia>
          <ixx>0.00425431</ixx>
          <ixy>6.65278e-07</ixy>
          <ixz>-1.49586e-05</ixz>
          <iyy>0.00411121</iyy>
          <iyz>0.000122735</iyz>
          <izz>0.000899307</izz>
        </inertia>
      </inertial>
      <collision name='right_wrist_3_link_collision'>
        <pose frame=''>0 0 0 0 -0 0</pose>
        <geometry>
          <mesh>
            <scale>1 1 1</scale>
            <uri>file://MovoRobot/movo_description//meshes/manipulation/jaco/collision/kinova_actuator_gearing.stl</uri>
          </mesh>
        </geometry>
        <surface>
          <contact>
            <ode>
              <kp>1e+06</kp>
              <kd>100</kd>
              <max_vel>100</max_vel>
              <min_depth>0.001</min_depth>
            </ode>
          </contact>
          <friction>
            <ode>
              <mu>1</mu>
              <mu2>1</mu2>
            </ode>
          </friction>
        </surface>
      </collision>
      <collision name='right_wrist_3_link_fixed_joint_lump__right_gripper_base_link_collision_1'>
        <pose frame=''>-0 0 0 0 -0 0</pose>
        <geometry>
          <mesh>
            <scale>1 1 1</scale>
            <uri>file://MovoRobot/movo_description//meshes/manipulation/kinova_grippers/collision/kg3_base_link.stl</uri>
          </mesh>
        </geometry>
        <surface>
          <contact>
            <ode>
              <kp>1e+06</kp>
              <kd>1</kd>
              <max_vel>0</max_vel>
              <min_depth>0.0001</min_depth>
            </ode>
          </contact>
          <friction>
            <ode>
              <mu>0.8</mu>
              <mu2>0.8</mu2>
            </ode>
          </friction>
        </surface>
      </collision>
      <visual name='right_wrist_3_link_visual'>
        <pose frame=''>0 0 0 0 -0 0</pose>
        <geometry>
          <mesh>
            <scale>1 1 1</scale>
            <uri>file://MovoRobot/movo_description//meshes/manipulation/jaco/visual/kinova_actuator_gearing.dae</uri>
          </mesh>
        </geometry>
        <material>
          <script>
            <uri>__default__</uri>
            <name>__default__</name>
          </script>
        </material>
      </visual>
      <visual name='right_wrist_3_link_fixed_joint_lump__right_gripper_base_link_visual_1'>
        <pose frame=''>-0 0 0 0 -0 0</pose>
        <geometry>
          <mesh>
            <scale>1 1 1</scale>
            <uri>file://MovoRobot/movo_description//meshes/manipulation/kinova_grippers/visual/kg3_base_link.dae</uri>
          </mesh>
        </geometry>
        <material>
          <script>
            <uri>__default__</uri>
            <name>__default__</name>
          </script>
        </material>
      </visual>
      <velocity_decay/>
      <gravity>1</gravity>
      <velocity_decay/>
      <self_collide>0</self_collide>
    </link>
    <joint name='right_wrist_3_joint' type='revolute'>
      <child>right_wrist_3_link</child>
      <parent>right_wrist_spherical_2_link</parent>
      <axis>
        <xyz>-1 -0 -0</xyz>
        <limit>
          <lower>-3.14159</lower>
          <upper>3.14159</upper>
          <effort>60000.8</effort>
          <velocity>0.921534</velocity>
        </limit>
        <dynamics>
          <damping>0.01</damping>
          <friction>0</friction>
          <spring_reference>0</spring_reference>
          <spring_stiffness>0</spring_stiffness>
        </dynamics>
        <use_parent_model_frame>1</use_parent_model_frame>
      </axis>
    </joint>


        <!--============================================-->
<link name='right_ee_link'>
      <pose frame=''>1.269 -0.13335 0.76147 -1.5708 -0 -0</pose>
      <inertial>
        <pose frame=''>-0.041189 0.002299 0.277881 0 -0 0</pose>
        <mass>1.79931</mass>
        <inertia>
          <ixx>100.112</ixx>
          <ixy>0.000216154</ixy>
          <ixz>-0.0205909</ixz>
          <iyy>100.116</iyy>
          <iyz>0.00114947</iyz>
          <izz>100.005</izz>
        </inertia>
      </inertial>
      <velocity_decay/>
        <!-- <visual name='right_ee_link'>
       <pose frame=''>0.0 0.0 0.0 0.0 0.0 0.0</pose> 
       <geometry>
        <sphere>
          <radius>0.1</radius>
        </sphere>
       </geometry>
       <material>
        <script>
          <uri>file://media/materials/scripts/gazebo.material</uri>
          <name>Gazebo/Grey</name>
        </script>
        <ambient>1 0 0 1.0</ambient>
      </material> 
   </visual> -->    
  </link>
    <joint name='right_ee_fixed_joint' type='revolute'>
      <child>right_ee_link</child>
      <parent>right_wrist_3_link</parent>
      <axis>
        <xyz>0 1 -0</xyz>
        <limit>
          <lower>0</lower>
          <upper>0</upper>
          <effort>0</effort>
          <velocity>0</velocity>
        </limit>
        <dynamics>
          <spring_reference>0</spring_reference>
          <spring_stiffness>0</spring_stiffness>
        </dynamics>
        <use_parent_model_frame>1</use_parent_model_frame>
      </axis>
    </joint>

<link name='right_knuckle_link'>
  <pose frame=''>1.23447 -0.13335 0.76147 -1.5708 -0 -0</pose>
  <inertial>
        <pose frame=''>-0.041189 0.002299 0.277881 0 -0 0</pose>
        <mass>1.79931</mass>
        <inertia>
          <ixx>100.112</ixx>
          <ixy>0.000216154</ixy>
          <ixz>-0.0205909</ixz>
          <iyy>100.116</iyy>
          <iyz>0.00114947</iyz>
          <izz>100.005</izz>
        </inertia>
      </inertial>
      <velocity_decay/>
      <visual name='wristSphere1'>
           <pose frame=''>0.2 0.0 0.0 0.0 0.0 0.0</pose> 
           <geometry>
            <sphere>
              <radius>0.012</radius>
            </sphere>
           </geometry>
           <material>
            <script>
              <uri>file://media/materials/scripts/gazebo.material</uri>
              <name>Gazebo/Grey</name>
            </script>
            <ambient>1 0 0 1.0</ambient>
          </material> 
       </visual>
       <visual name='wristSphere2'>
           <pose frame=''>0.0 0.2 0.0 0.0 0.0 0.0</pose> 
           <geometry>
            <sphere>
              <radius>0.012</radius>
            </sphere>
           </geometry>
           <material>
            <script>
              <uri>file://media/materials/scripts/gazebo.material</uri>
              <name>Gazebo/Grey</name>
            </script>
            <ambient>0 1 0 1.0</ambient>
          </material> 
       </visual>
       <visual name='knuckleSphere3'>
           <pose frame=''>0.0 0.0 0.2 0.0 0.0 0.0</pose> 
           <geometry>
            <sphere>
              <radius>0.01</radius>
            </sphere>
           </geometry>
           <material>
            <script>
              <uri>file://media/materials/scripts/gazebo.material</uri>
              <name>Gazebo/Grey</name>
            </script>
            <ambient>0 0 1 1.0</ambient>
          </material> 
       </visual>
       <visual name='knuckleSphere4'>
           <pose frame=''>0.0 0.0 0.0 0.0 0.0 0.0</pose> 
           <geometry>
            <sphere>
              <radius>0.023</radius>
            </sphere>
           </geometry>
           <material>
            <script>
              <uri>file://media/materials/scripts/gazebo.material</uri>
              <name>Gazebo/Grey</name>
            </script>
            <ambient>0 0 1 1.0</ambient>
          </material> 
       </visual>
       <collision name='right_knuckle_collision'>
           <pose frame=''>0.0 0.0 0.0 0.0 0.0 0.0</pose> 
           <geometry>
            <sphere>
              <!--radius>0.0175</radius-->
              <radius>0.021</radius>
            </sphere>
           </geometry> 
           <max_contacts>10</max_contacts>          
       </collision>
</link>

<joint name='right_knuckle_fixed_joint' type='revolute'>
      <child>right_knuckle_link</child>
      <parent>right_ee_link</parent>
      <axis>
        <xyz>0 1 -0</xyz>
        <limit>
          <lower>0</lower>
          <upper>0</upper>
          <effort>0</effort>
          <velocity>0</velocity>
        </limit>
        <dynamics>
          <spring_reference>0</spring_reference>
          <spring_stiffness>0</spring_stiffness>
        </dynamics>
        <use_parent_model_frame>1</use_parent_model_frame>
      </axis>
    </joint>


     <!--============================================-->





    <link name='right_gripper_finger1_knuckle_link'>
      <pose frame=''>1.22393 -0.136145 0.730152 3.08956 -1.39126 -1.62279</pose>
      <inertial>
        <pose frame=''>-0.028253 -0.032416 0 0 -0 0</pose>
        <mass>0.021817</mass>
        <inertia>
          <ixx>9.39482e-06</ixx>
          <ixy>-1.3461e-06</ixy>
          <ixz>0</ixz>
          <iyy>4.07539e-06</iyy>
          <iyz>0</iyz>
          <izz>1.14702e-05</izz>
        </inertia>
      </inertial>
      <collision name='right_gripper_finger1_knuckle_link_collision'>
        <pose frame=''>0 0 0 0 -0 0</pose>
        <geometry>
          <mesh>
            <scale>1 1 1</scale>
            <uri>file://MovoRobot/movo_description//meshes/manipulation/kinova_grippers/collision/finger_knuckle.stl</uri>
          </mesh>
        </geometry>
        <surface>
          <contact>
            <ode>
              <kp>1e+06</kp>
              <kd>1</kd>
              <max_vel>0</max_vel>
              <min_depth>0.0001</min_depth>
            </ode>
          </contact>
          <friction>
            <ode>
              <mu>0.8</mu>
              <mu2>0.8</mu2>
            </ode>
          </friction>
        </surface>
      </collision>
      <collision name='right_gripper_finger1_knuckle_link_fixed_joint_lump__right_gripper_finger1_finger_tip_link_collision_1'>
        <pose frame=''>-0.024598 -0.036051 0 0 -0 0</pose>
        <geometry>
          <mesh>
            <scale>1 1 1</scale>
            <uri>file://MovoRobot/movo_description//meshes/manipulation/kinova_grippers/collision/finger_tip.stl</uri>
          </mesh>
        </geometry>
        <surface>
          <contact>
            <ode>
              <kp>1e+06</kp>
              <kd>1</kd>
              <max_vel>0</max_vel>
              <min_depth>0.0001</min_depth>
            </ode>
          </contact>
          <friction>
            <ode>
              <mu>0.8</mu>
              <mu2>0.8</mu2>
            </ode>
          </friction>
        </surface>
      </collision>
      <visual name='right_gripper_finger1_knuckle_link_visual'>
        <pose frame=''>0 0 0 0 -0 0</pose>
        <geometry>
          <mesh>
            <scale>1 1 1</scale>
            <uri>file://MovoRobot/movo_description//meshes/manipulation/kinova_grippers/visual/finger_knuckle.dae</uri>
          </mesh>
        </geometry>
        <material>
          <script>
            <uri>__default__</uri>
            <name>__default__</name>
          </script>
        </material>
      </visual>
      <visual name='right_gripper_finger1_knuckle_link_fixed_joint_lump__right_gripper_finger1_finger_tip_link_visual_1'>
        <pose frame=''>-0.024598 -0.036051 0 0 -0 0</pose>
        <geometry>
          <mesh>
            <scale>1 1 1</scale>
            <uri>file://MovoRobot/movo_description//meshes/manipulation/kinova_grippers/visual/finger_tip.dae</uri>
          </mesh>
        </geometry>
        <material>
          <script>
            <uri>__default__</uri>
            <name>__default__</name>
          </script>
        </material>
      </visual>
      <velocity_decay/>
      <gravity>1</gravity>
      <velocity_decay/>
      <self_collide>0</self_collide>
    </link>
    <joint name='right_gripper_finger1_joint' type='revolute'>
      <child>right_gripper_finger1_knuckle_link</child>
      <parent>right_wrist_3_link</parent>
      <axis>
        <xyz>-0.103009 -0.978563 -0.178336</xyz>
        <limit>
          <lower>0</lower>
          <upper>0.986111</upper>
          <effort>3</effort>
          <velocity>1</velocity>
        </limit>
        <dynamics>
          <spring_reference>0</spring_reference>
          <spring_stiffness>0</spring_stiffness>
        </dynamics>
        <use_parent_model_frame>1</use_parent_model_frame>
      </axis>
    </joint>
    <link name='right_gripper_finger2_knuckle_link'>
      <pose frame=''>1.224 -0.111061 0.788723 3.14159 1.38609 -1.5708</pose>
      <inertial>
        <pose frame=''>-0.028253 -0.032416 0 0 -0 0</pose>
        <mass>0.021817</mass>
        <inertia>
          <ixx>9.39482e-06</ixx>
          <ixy>-1.3461e-06</ixy>
          <ixz>0</ixz>
          <iyy>4.07539e-06</iyy>
          <iyz>0</iyz>
          <izz>1.14702e-05</izz>
        </inertia>
      </inertial>
      <collision name='right_gripper_finger2_knuckle_link_collision'>
        <pose frame=''>0 0 0 0 -0 0</pose>
        <geometry>
          <mesh>
            <scale>1 1 1</scale>
            <uri>file://MovoRobot/movo_description//meshes/manipulation/kinova_grippers/collision/finger_knuckle.stl</uri>
          </mesh>
        </geometry>
        <surface>
          <contact>
            <ode>
              <kp>1e+06</kp>
              <kd>1</kd>
              <max_vel>0</max_vel>
              <min_depth>0.0001</min_depth>
            </ode>
          </contact>
          <friction>
            <ode>
              <mu>0.8</mu>
              <mu2>0.8</mu2>
            </ode>
          </friction>
        </surface>
      </collision>
      <collision name='right_gripper_finger2_knuckle_link_fixed_joint_lump__right_gripper_finger2_finger_tip_link_collision_1'>
        <pose frame=''>-0.024598 -0.036051 0 0 -0 0</pose>
        <geometry>
          <mesh>
            <scale>1 1 1</scale>
            <uri>file://MovoRobot/movo_description//meshes/manipulation/kinova_grippers/collision/finger_tip.stl</uri>
          </mesh>
        </geometry>
        <surface>
          <contact>
            <ode>
              <kp>1e+06</kp>
              <kd>1</kd>
              <max_vel>0</max_vel>
              <min_depth>0.0001</min_depth>
            </ode>
          </contact>
          <friction>
            <ode>
              <mu>0.8</mu>
              <mu2>0.8</mu2>
            </ode>
          </friction>
        </surface>
      </collision>
      <visual name='right_gripper_finger2_knuckle_link_visual'>
        <pose frame=''>0 0 0 0 -0 0</pose>
        <geometry>
          <mesh>
            <scale>1 1 1</scale>
            <uri>file://MovoRobot/movo_description//meshes/manipulation/kinova_grippers/visual/finger_knuckle.dae</uri>
          </mesh>
        </geometry>
        <material>
          <script>
            <uri>__default__</uri>
            <name>__default__</name>
          </script>
        </material>
      </visual>
      <visual name='right_gripper_finger2_knuckle_link_fixed_joint_lump__right_gripper_finger2_finger_tip_link_visual_1'>
        <pose frame=''>-0.024598 -0.036051 0 0 -0 0</pose>
        <geometry>
          <mesh>
            <scale>1 1 1</scale>
            <uri>file://MovoRobot/movo_description//meshes/manipulation/kinova_grippers/visual/finger_tip.dae</uri>
          </mesh>
        </geometry>
        <material>
          <script>
            <uri>__default__</uri>
            <name>__default__</name>
          </script>
        </material>
      </visual>
      <velocity_decay/>
      <gravity>1</gravity>
      <velocity_decay/>
      <self_collide>0</self_collide>
    </link>
    <joint name='right_gripper_finger2_joint' type='revolute'>
      <child>right_gripper_finger2_knuckle_link</child>
      <parent>right_wrist_3_link</parent>
      <axis>
        <xyz>-0 0.982991 -0.183655</xyz>
        <limit>
          <lower>0</lower>
          <upper>0.986111</upper>
          <effort>3</effort>
          <velocity>1</velocity>
        </limit>
        <dynamics>
          <spring_reference>0</spring_reference>
          <spring_stiffness>0</spring_stiffness>
        </dynamics>
        <use_parent_model_frame>1</use_parent_model_frame>
      </axis>
    </joint>
    <link name='right_gripper_finger3_knuckle_link'>
      <pose frame=''>1.22402 -0.155634 0.788693 0 1.3861 1.5708</pose>
      <inertial>
        <pose frame=''>-0.028253 -0.032416 0 0 -0 0</pose>
        <mass>0.021817</mass>
        <inertia>
          <ixx>9.39482e-06</ixx>
          <ixy>-1.3461e-06</ixy>
          <ixz>0</ixz>
          <iyy>4.07539e-06</iyy>
          <iyz>0</iyz>
          <izz>1.14702e-05</izz>
        </inertia>
      </inertial>
      <collision name='right_gripper_finger3_knuckle_link_collision'>
        <pose frame=''>0 0 0 0 -0 0</pose>
        <geometry>
          <mesh>
            <scale>1 1 1</scale>
            <uri>file://MovoRobot/movo_description//meshes/manipulation/kinova_grippers/collision/finger_knuckle.stl</uri>
          </mesh>
        </geometry>
        <surface>
          <contact>
            <ode>
              <kp>1e+06</kp>
              <kd>1</kd>
              <max_vel>0</max_vel>
              <min_depth>0.0001</min_depth>
            </ode>
          </contact>
          <friction>
            <ode>
              <mu>0.8</mu>
              <mu2>0.8</mu2>
            </ode>
          </friction>
        </surface>
      </collision>
      <collision name='right_gripper_finger3_knuckle_link_fixed_joint_lump__right_gripper_finger3_finger_tip_link_collision_1'>
        <pose frame=''>-0.024598 -0.036051 0 0 -0 0</pose>
        <geometry>
          <mesh>
            <scale>1 1 1</scale>
            <uri>file://MovoRobot/movo_description//meshes/manipulation/kinova_grippers/collision/finger_tip.stl</uri>
          </mesh>
        </geometry>
        <surface>
          <contact>
            <ode>
              <kp>1e+06</kp>
              <kd>1</kd>
              <max_vel>0</max_vel>
              <min_depth>0.0001</min_depth>
            </ode>
          </contact>
          <friction>
            <ode>
              <mu>0.8</mu>
              <mu2>0.8</mu2>
            </ode>
          </friction>
        </surface>
      </collision>
      <visual name='right_gripper_finger3_knuckle_link_visual'>
        <pose frame=''>0 0 0 0 -0 0</pose>
        <geometry>
          <mesh>
            <scale>1 1 1</scale>
            <uri>file://MovoRobot/movo_description//meshes/manipulation/kinova_grippers/visual/finger_knuckle.dae</uri>
          </mesh>
        </geometry>
        <material>
          <script>
            <uri>__default__</uri>
            <name>__default__</name>
          </script>
        </material>
      </visual>
      <visual name='right_gripper_finger3_knuckle_link_fixed_joint_lump__right_gripper_finger3_finger_tip_link_visual_1'>
        <pose frame=''>-0.024598 -0.036051 0 0 -0 0</pose>
        <geometry>
          <mesh>
            <scale>1 1 1</scale>
            <uri>file://MovoRobot/movo_description//meshes/manipulation/kinova_grippers/visual/finger_tip.dae</uri>
          </mesh>
        </geometry>
        <material>
          <script>
            <uri>__default__</uri>
            <name>__default__</name>
          </script>
        </material>
      </visual>
      <velocity_decay/>
      <gravity>1</gravity>
      <velocity_decay/>
      <self_collide>0</self_collide>
    </link>
    <joint name='right_gripper_finger3_joint' type='revolute'>
      <child>right_gripper_finger3_knuckle_link</child>
      <parent>right_wrist_3_link</parent>
      <axis>
        <xyz>-0 0.982992 0.183648</xyz>
        <limit>
          <lower>0</lower>
          <upper>0.986111</upper>
          <effort>3</effort>
          <velocity>1</velocity>
        </limit>
        <dynamics>
          <spring_reference>0</spring_reference>
          <spring_stiffness>0</spring_stiffness>
        </dynamics>
        <use_parent_model_frame>1</use_parent_model_frame>
      </axis>
    </joint>
    <link name='mid_body_link'>
      <pose frame=''>0.07714 0 0.470076 0 -0 0</pose>
      <inertial>
        <pose frame=''>-0.07714 0 0.026602 0 -0 0</pose>
        <mass>2.24684</mass>
        <inertia>
          <ixx>0.067276</ixx>
          <ixy>0</ixy>
          <ixz>0</ixz>
          <iyy>0.073946</iyy>
          <iyz>0</iyz>
          <izz>0.102656</izz>
        </inertia>
      </inertial>
      <visual name='mid_body_link_visual'>
        <pose frame=''>0 0 0 0 -0 0</pose>
        <geometry>
          <mesh>
            <scale>1 1 1</scale>
            <uri>file://MovoRobot/movo_description//meshes/movo_body/movo_mid_body.dae</uri>
          </mesh>
        </geometry>
        <material>
          <script>
            <uri>__default__</uri>
            <name>__default__</name>
          </script>
        </material>
      </visual>
      <gravity>1</gravity>
      <velocity_decay/>
      <self_collide>0</self_collide>
      <gravity>0</gravity>
    </link>
    <joint name='mid_body_joint' type='prismatic'>
      <child>mid_body_link</child>
      <parent>base_link</parent>
      <axis>
        <xyz>0 0 1</xyz>
        <limit>
          <lower>0</lower>
          <upper>0.254561</upper>
          <effort>1000</effort>
          <velocity>0.2</velocity>
        </limit>
        <dynamics>
          <damping>0</damping>
          <friction>0</friction>
          <spring_reference>0</spring_reference>
          <spring_stiffness>0</spring_stiffness>
        </dynamics>
        <use_parent_model_frame>1</use_parent_model_frame>
      </axis>
    </joint>






















    
    <!-- <plugin name='gazebo_ros_control' filename='libgazebo_ros_control.so'>
      <robotNamespace>/</robotNamespace>
    </plugin>
    <plugin name='object_controller' filename='libgazebo_ros_force_based_move.so'>
      <robotNamespace>/</robotNamespace>
      <commandTopic>/movo/cmd_vel</commandTopic>
      <odometryTopic>/movo/odometry/wheel_odometry</odometryTopic>
      <odometryFrame>odom</odometryFrame>
      <odometryRate>100.0</odometryRate>
      <cmdVelTimeOut>0.2</cmdVelTimeOut>
      <robotBaseFrame>base_link</robotBaseFrame>
      <publishOdometryTf>0</publishOdometryTf>
      <yaw_velocity_p_gain>500.0</yaw_velocity_p_gain>
      <x_velocity_p_gain>10000.0</x_velocity_p_gain>
      <y_velocity_p_gain>10000.0</y_velocity_p_gain>
    </plugin>
    <plugin name='gazebo_ros_p3d' filename='libgazebo_ros_p3d.so'>
      <bodyName>base_link</bodyName>
      <topicName>ground_truth_odom</topicName>
      <alwaysOn>true</alwaysOn>
      <updateRate>100.0</updateRate>
    </plugin>
    <plugin name='sic_imu_controller' filename='libhector_gazebo_ros_imu.so'>
      <alwaysOn>1</alwaysOn>
      <updateRate>50.0</updateRate>
      <topicName>/movo/feedback/sic_imu</topicName>
      <accelDrift>0.0005 0.0005 0.0005</accelDrift>
      <accelGaussianNoise>0.0005 0.0005 0.0005</accelGaussianNoise>
      <rateDrift>0.0005 0.0005 0.0005</rateDrift>
      <rateGaussianNoise>0.00005 0.00005 0.00005</rateGaussianNoise>
      <headingDrift>0.00005</headingDrift>
      <headingGaussianNoise>0.00005</headingGaussianNoise>
      <bodyName>base_link</bodyName>
      <xyzOffset>-0.0326421 -0.0899448 -0.0844008</xyzOffset>
      <rpyOffset>-0.0548311 -4.63139e-08 0.0274155</rpyOffset>
    </plugin>
    <plugin name='mid_body_mimic' filename='libroboticsgroup_gazebo_mimic_joint_plugin.so'>
      <joint>linear_joint</joint>
      <mimicJoint>mid_body_joint</mimicJoint>
      <multiplier>0.5</multiplier>
      <offset>0.0</offset>
      <maxEffort>100000.0</maxEffort>
    </plugin>
    <plugin name='right_mimic_finger_1_2' filename='libroboticsgroup_gazebo_mimic_joint_plugin.so'>
      <joint>right_gripper_finger1_joint</joint>
      <mimicJoint>right_gripper_finger2_joint</mimicJoint>
    </plugin>
    <plugin name='right_mimic_finger_1_3' filename='libroboticsgroup_gazebo_mimic_joint_plugin.so'>
      <joint>right_gripper_finger1_joint</joint>
      <mimicJoint>right_gripper_finger3_joint</mimicJoint>
    </plugin>
    <plugin name='left_mimic_finger_1_2' filename='libroboticsgroup_gazebo_mimic_joint_plugin.so'>
      <joint>left_gripper_finger1_joint</joint>
      <mimicJoint>left_gripper_finger2_joint</mimicJoint>
    </plugin>
    <plugin name='left_mimic_finger_1_3' filename='libroboticsgroup_gazebo_mimic_joint_plugin.so'>
      <joint>left_gripper_finger1_joint</joint>
      <mimicJoint>left_gripper_finger3_joint</mimicJoint>
    </plugin>
    <plugin name='gazebo_right_grasp_fix' filename='libgazebo_grasp_fix.so'>
      <arm>
        <arm_name>right_arm</arm_name>
        <palm_link>right_wrist_3_link</palm_link>
        <gripper_link>right_gripper_finger1_knuckle_link</gripper_link>
        <gripper_link>right_gripper_finger2_knuckle_link</gripper_link>
        <gripper_link>right_gripper_finger3_knuckle_link</gripper_link>
      </arm>
      <forces_angle_tolerance>100</forces_angle_tolerance>
      <update_rate>50</update_rate>
      <grip_count_threshold>1</grip_count_threshold>
      <max_grip_count>8</max_grip_count>
      <release_tolerance>0.006</release_tolerance>
      <disable_collisions_on_attach>true</disable_collisions_on_attach>
      <contact_topic>right_gripper/contacts</contact_topic>
    </plugin>
    <static>0</static>
    <plugin name='gazebo_left_grasp_fix' filename='libgazebo_grasp_fix.so'>
      <arm>
        <arm_name>left_arm</arm_name>
        <palm_link>left_wrist_3_link</palm_link>
        <gripper_link>left_gripper_finger1_knuckle_link</gripper_link>
        <gripper_link>left_gripper_finger2_knuckle_link</gripper_link>
        <gripper_link>left_gripper_finger3_knuckle_link</gripper_link>
      </arm>
      <forces_angle_tolerance>100</forces_angle_tolerance>
      <update_rate>50</update_rate>
      <grip_count_threshold>1</grip_count_threshold>
      <max_grip_count>8</max_grip_count>
      <release_tolerance>0.006</release_tolerance>
      <disable_collisions_on_attach>true</disable_collisions_on_attach>
      <contact_topic>left_gripper/contacts</contact_topic>
    </plugin> -->
  </model>
</sdf>
